<sdf version='1.7'>
  <model name='ur3_delto'>
    <self_collide>0</self_collide>
    <link name="base_link">
			<pose relative_to="__model__">0 0 0 0 0 0</pose>
			<inertial>
				<mass>2</mass>
				<inertia>
					<ixx>0.00305317</ixx>
					<ixy>0</ixy>
					<ixz>0</ixz>
					<iyy>0.00305317</iyy>
					<iyz>0</iyz>
					<izz>0.005625</izz>
				</inertia>
			</inertial>
			<collision name="base_link_collision">
				<geometry>
					<mesh>
						<uri>model://ur3/meshes/collision/base.stl</uri>
					</mesh>
				</geometry>
			</collision>
			<visual name="base_link_visual">
				<geometry>
					<mesh>
						<uri>model://ur3/meshes/visual/base.dae</uri>
					</mesh>
				</geometry>
			</visual>
		</link>
		<joint name="shoulder_pan_joint" type="revolute">
			<pose relative_to="base_link">0 0 0.1519 0 -0 0</pose>
			<parent>base_link</parent>
			<child>shoulder_link</child>
			<axis>
				<xyz>0 0 1</xyz>
				<limit>
					<lower>-6.28319</lower>
					<upper>6.28319</upper>
					<effort>330</effort>
					<velocity>2.16</velocity>
				</limit>
				<dynamics>
					<damping>0</damping>
					<friction>0</friction>
					<spring_reference>0</spring_reference>
					<spring_stiffness>0</spring_stiffness>
				</dynamics>
			</axis>
		</joint>
		<link name="shoulder_link">
			<pose relative_to="shoulder_pan_joint">0 0 0 0 -0 0</pose>
			<inertial>
				<mass>2</mass>
				<inertia>
					<ixx>0.00809316</ixx>
					<ixy>0</ixy>
					<ixz>0</ixz>
					<iyy>0.00809316</iyy>
					<iyz>0</iyz>
					<izz>0.005625</izz>
				</inertia>
			</inertial>
			<collision name="shoulder_link_collision">
				<geometry>
					<mesh>
						<uri>model://ur3/meshes/collision/shoulder.stl</uri>
					</mesh>
				</geometry>
			</collision>
			<visual name="shoulder_link_visual">
				<geometry>
					<mesh>
						<uri>model://ur3/meshes/visual/shoulder.dae</uri>
					</mesh>
				</geometry>
			</visual>
			<self_collide>1</self_collide>
		</link>
		<joint name="shoulder_lift_joint" type="revolute">
			<pose relative_to="shoulder_link">0 0.1198 0 0 1.5708 0</pose>
			<parent>shoulder_link</parent>
			<child>upper_arm_link</child>
			<axis>
				<xyz>0 1 0</xyz>
				<limit>
					<lower>-6.28319</lower>
					<upper>6.28319</upper>
					<effort>330</effort>
					<velocity>2.16</velocity>
				</limit>
				<dynamics>
					<damping>0</damping>
					<friction>0</friction>
					<spring_reference>0</spring_reference>
					<spring_stiffness>0</spring_stiffness>
				</dynamics>
			</axis>
		</joint>
		<link name="upper_arm_link">
			<pose relative_to="shoulder_lift_joint">0 0 0 0 -0 0</pose>
			<inertial>
				<pose>0 0 0.121825 0 -0 0</pose>
				<mass>3.42</mass>
				<inertia>
					<ixx>0.0217285</ixx>
					<ixy>0</ixy>
					<ixz>0</ixz>
					<iyy>0.0217285</iyy>
					<iyz>0</iyz>
					<izz>0.00961875</izz>
				</inertia>
			</inertial>
			<collision name="upper_arm_link_collision">
				<geometry>
					<mesh>
						<uri>model://ur3/meshes/collision/upperarm.stl</uri>
					</mesh>
				</geometry>
			</collision>
			<visual name="upper_arm_link_visual">
				<geometry>
					<mesh>
						<uri>model://ur3/meshes/visual/upperarm.dae</uri>
					</mesh>
				</geometry>
			</visual>
			<self_collide>1</self_collide>
		</link>
		<joint name="elbow_joint" type="revolute">
			<pose relative_to="upper_arm_link">0 -0.0925 0.24365 0 -0 0</pose>
			<parent>upper_arm_link</parent>
			<child>forearm_link</child>
			<axis>
				<xyz>0 1 0</xyz>
				<limit>
					<lower>-3.14159</lower>
					<upper>3.14159</upper>
					<effort>150</effort>
					<velocity>3.15</velocity>
				</limit>
				<dynamics>
					<damping>0</damping>
					<friction>0</friction>
					<spring_reference>0</spring_reference>
					<spring_stiffness>0</spring_stiffness>
				</dynamics>
			</axis>
		</joint>
		<link name="forearm_link">
			<pose relative_to="elbow_joint">0 0 0 0 -0 0</pose>
			<inertial>
				<pose>0 0 0.106625 0 -0 0</pose>
				<mass>1.26</mass>
				<inertia>
					<ixx>0.00654681</ixx>
					<ixy>0</ixy>
					<ixz>0</ixz>
					<iyy>0.00654681</iyy>
					<iyz>0</iyz>
					<izz>0.00354375</izz>
				</inertia>
			</inertial>
			<collision name="forearm_link_collision">
				<geometry>
					<mesh>
						<uri>model://ur3/meshes/collision/forearm.stl</uri>
					</mesh>
				</geometry>
			</collision>
			<visual name="forearm_link_visual">
				<geometry>
					<mesh>
						<uri>model://ur3/meshes/visual/forearm.dae</uri>
					</mesh>
				</geometry>
			</visual>
			<self_collide>1</self_collide>
		</link>
		<joint name="wrist_1_joint" type="revolute">
			<pose relative_to="forearm_link">0 0 0.21325 0 1.5708 0</pose>
			<parent>forearm_link</parent>
			<child>wrist_1_link</child>
			<axis>
				<xyz>0 1 0</xyz>
				<limit>
					<lower>-6.28319</lower>
					<upper>6.28319</upper>
					<effort>54</effort>
					<velocity>3.2</velocity>
				</limit>
				<dynamics>
					<damping>0</damping>
					<friction>0</friction>
					<spring_reference>0</spring_reference>
					<spring_stiffness>0</spring_stiffness>
				</dynamics>
			</axis>
		</joint>
		<link name="wrist_1_link">
			<pose relative_to="wrist_1_joint">0 0 0 0 -0 0</pose>
			<inertial>
				<pose>0 0.08505 0 0 -0 0</pose>
				<mass>0.8</mass>
				<inertia>
					<ixx>0.002085</ixx>
					<ixy>0</ixy>
					<ixz>0</ixz>
					<iyy>0.002085</iyy>
					<iyz>0</iyz>
					<izz>0.00225</izz>
				</inertia>
			</inertial>
			<collision name="wrist_1_link_collision">
				<geometry>
					<mesh>
						<uri>model://ur3/meshes/collision/wrist1.stl</uri>
					</mesh>
				</geometry>
			</collision>
			<visual name="wrist_1_link_visual">
				<geometry>
					<mesh>
						<uri>model://ur3/meshes/visual/wrist1.dae</uri>
					</mesh>
				</geometry>
			</visual>
			<self_collide>1</self_collide>
		</link>
		<joint name="wrist_2_joint" type="revolute">
			<pose relative_to="wrist_1_link">0 0.08505 0 0 -0 0</pose>
			<parent>wrist_1_link</parent>
			<child>wrist_2_link</child>
			<axis>
				<xyz>0 0 1</xyz>
				<limit>
					<lower>-6.28319</lower>
					<upper>6.28319</upper>
					<effort>54</effort>
					<velocity>3.2</velocity>
				</limit>
				<dynamics>
					<damping>0</damping>
					<friction>0</friction>
					<spring_reference>0</spring_reference>
					<spring_stiffness>0</spring_stiffness>
				</dynamics>
			</axis>
		</joint>
		<link name="wrist_2_link">
			<pose relative_to="wrist_2_joint">0 0 0 0 -0 0</pose>
			<inertial>
				<pose>0 0 0.08535 0 -0 0</pose>
				<mass>0.8</mass>
				<inertia>
					<ixx>0.002085</ixx>
					<ixy>0</ixy>
					<ixz>0</ixz>
					<iyy>0.002085</iyy>
					<iyz>0</iyz>
					<izz>0.00225</izz>
				</inertia>
			</inertial>
			<collision name="wrist_2_link_collision">
				<geometry>
					<mesh>
						<uri>model://ur3/meshes/collision/wrist2.stl</uri>
					</mesh>
				</geometry>
			</collision>
			<visual name="wrist_2_link_visual">
				<geometry>
					<mesh>
						<uri>model://ur3/meshes/visual/wrist2.dae</uri>
					</mesh>
				</geometry>
			</visual>
			<self_collide>1</self_collide>
		</link>
		<joint name="wrist_3_joint" type="revolute">
			<pose relative_to="wrist_2_link">0 0 0.08535 0 -0 0</pose>
			<parent>wrist_2_link</parent>
			<child>wrist_3_link</child>
			<axis>
				<xyz>0 1 0</xyz>
				<limit>
					<lower>-6.28319</lower>
					<upper>6.28319</upper>
					<effort>54</effort>
					<velocity>3.2</velocity>
				</limit>
				<dynamics>
					<damping>0</damping>
					<friction>0</friction>
					<spring_reference>0</spring_reference>
					<spring_stiffness>0</spring_stiffness>
				</dynamics>
			</axis>
		</joint>
		<link name="wrist_3_link">
			<pose relative_to="wrist_3_joint">0 0 0 0 -0 0</pose>
			<inertial>
				<pose>0 0.0619 0 1.5708 -0 0</pose>
				<mass>0.35</mass>
				<inertia>
					<ixx>0.000136267</ixx>
					<ixy>0</ixy>
					<ixz>0</ixz>
					<iyy>0.000136267</iyy>
					<iyz>0</iyz>
					<izz>0.0001792</izz>
				</inertia>
			</inertial>
			<collision name="wrist_3_link_collision">
				<geometry>
					<mesh>
						<uri>model://ur3/meshes/collision/wrist3.stl</uri>
					</mesh>
				</geometry>
			</collision>
			<visual name="wrist_3_link_visual">
				<geometry>
					<mesh>
						<uri>model://ur3/meshes/visual/wrist3.dae</uri>
					</mesh>
				</geometry>
			</visual>
			<self_collide>1</self_collide>
		</link>

    <joint name='ee_fixed_joint' type='fixed'>
      <pose relative_to='wrist_3_link'>0 0 0 0 -0 1.5708</pose>
      <parent>wrist_3_link</parent>
      <child>ee_link</child>
    </joint>
    <link name='ee_link'>
      <inertial>
        <mass>0.001</mass>
        <inertia>
          <ixx>1.66667e-08</ixx>
          <ixy>0</ixy>
          <ixz>0</ixz>
          <iyy>1.66667e-08</iyy>
          <iyz>0</iyz>
          <izz>1.66667e-08</izz>
        </inertia>
      </inertial>
      <collision name='collision'>
        <geometry>
          <box>
            <size>0.01 0.01 0.01</size>
          </box>
        </geometry>
      </collision>
      <self_collide>1</self_collide>
    </link>
    <link name='delto_base_link'>
      <pose relative_to='ur3_delto_joint'>0 0 0.19 0 0 1.57</pose>
      <inertial>
        <pose>0.000455 -2e-06 -0.052186 6e-06 0.003295 -0.000449</pose>
        <mass>0.370</mass>
        <inertia>
          <ixx>0.00099359</ixx>
          <ixy>0</ixy>
          <ixz>0</ixz>
          <iyy>0.000980252</iyy>
          <iyz>0</iyz>
          <izz>0.00031782</izz>
        </inertia>
      </inertial>
      <collision name='delto_base_link_collision'>
        <pose>0.000455 -2e-06 -0.052186 6e-06 0.003295 -0.000449</pose>
        <geometry>
          <mesh>
            <scale>1 1 1</scale>
            <uri>model://delto3f/meshes/base_link.stl</uri>
          </mesh>
        </geometry>
      </collision>
      <visual name='delto_base_link_visual'>
        <pose>0.000455 -2e-06 -0.052186 6e-06 0.003295 -0.000449</pose>
        <geometry>
          <mesh>
            <scale>1 1 1</scale>
            <uri>model://delto3f/meshes/base_link.stl</uri>
          </mesh>
        </geometry>
        <material>
          <ambient>0.05 0.05 0.05 1</ambient>
          <diffuse>0.1 0.1 0.1 1</diffuse>
          <specular>0.1 0.1 0.1 1</specular>
        </material>
      </visual>
      <self_collide>1</self_collide>
    </link>
    <joint name='F1M1' type='revolute'>
      <pose relative_to='delto_base_link'>0.0265 0 0 0 -0 0</pose>
      <parent>delto_base_link</parent>
      <child>F1_01</child>
      <axis>
        <xyz>0 0 1</xyz>
        <limit>
          <lower>-1.0472</lower>
          <upper>1.0472</upper>
          <effort>10</effort>
          <velocity>5</velocity>
        </limit>
        <dynamics>
          <damping>0.1</damping>
          <friction>0.1</friction>
          <spring_reference>0</spring_reference>
          <spring_stiffness>0</spring_stiffness>
        </dynamics>
      </axis>
    </joint>
    <link name='F1_01'>
      <pose relative_to='F1M1'>0 0 0 0 -0 0</pose>
      <inertial>
        <pose>0.000391 0 -0.014 -0.176624 -2e-06 1.57079</pose>
        <mass>0.061</mass>
        <inertia>
          <ixx>1.924e-05</ixx>
          <ixy>0</ixy>
          <ixz>0</ixz>
          <iyy>1.70941e-05</iyy>
          <iyz>0</iyz>
          <izz>5.94788e-06</izz>
        </inertia>
      </inertial>
      <collision name='F1_01_collision'>
        <pose>0.001898 -1e-06 -0.022984 -0.144392 2e-05 1.57092</pose>
        <geometry>
          <mesh>
            <scale>1 1 1</scale>
            <uri>model://delto3f/meshes/link_01.stl</uri>
          </mesh>
        </geometry>
      </collision>
      <visual name='F1_01_visual'>
        <pose>0.001898 -1e-06 -0.022984 -0.144392 2e-05 1.57092</pose>
        <geometry>
          <mesh>
            <scale>1 1 1</scale>
            <uri>model://delto3f/meshes/link_01.stl</uri>
          </mesh>
        </geometry>
        <material>
          <ambient>0.05 0.05 0.05 1</ambient>
          <diffuse>0.1 0.1 0.1 1</diffuse>
          <specular>0.1 0.1 0.1 1</specular>
        </material>
      </visual>
      <self_collide>1</self_collide>
    </link>
    <joint name='F1M2' type='revolute'>
      <pose relative_to='F1_01'>0 0 0 3e-06 -1.57079 3.14159</pose>
      <parent>F1_01</parent>
      <child>F1_02</child>
      <axis>
        <xyz>0 0 1</xyz>
        <limit>
          <lower>-1.76278</lower>
          <upper>1.76278</upper>
          <effort>10</effort>
          <velocity>5</velocity>
        </limit>
        <dynamics>
          <damping>0.1</damping>
          <friction>0.1</friction>
          <spring_reference>0</spring_reference>
          <spring_stiffness>0</spring_stiffness>
        </dynamics>
      </axis>
    </joint>
    <link name='F1_02'>
      <pose relative_to='F1M2'>0 0 0 0 -0 0</pose>
      <inertial>
        <pose>0.01 3e-06 0.016 -0.003689 0.316886 -0.002774</pose>
        <mass>0.025</mass>
        <inertia>
          <ixx>7.1648e-06</ixx>
          <ixy>0</ixy>
          <ixz>0</ixz>
          <iyy>6.31302e-06</iyy>
          <iyz>0</iyz>
          <izz>3.27418e-06</izz>
        </inertia>
      </inertial>
      <collision name='F1_02_collision'>
        <pose>0.010322 0.000268 0.013591 -0.031181 0.375739 -0.024334</pose>
        <geometry>
          <mesh>
            <scale>1 1 1</scale>
            <uri>model://delto3f/meshes/link_02.stl</uri>
          </mesh>
        </geometry>
        <self_collide>1</self_collide>
      </collision>
      <visual name='F1_02_visual'>
        <pose>0.010322 0.000268 0.013591 -0.031181 0.375739 -0.024334</pose>
        <geometry>
          <mesh>
            <scale>1 1 1</scale>
            <uri>model://delto3f/meshes/link_02.stl</uri>
          </mesh>
        </geometry>
        <material>
          <ambient>0.05 0.05 0.05 1</ambient>
          <diffuse>0.1 0.1 0.1 1</diffuse>
          <specular>0.1 0.1 0.1 1</specular>
        </material>
      </visual>
      <self_collide>1</self_collide>
    </link>
    <joint name='F1M3' type='revolute'>
      <pose relative_to='F1_02'>0.02022 0 0.03136 1.57079 -1.57079 3.14159</pose>
      <parent>F1_02</parent>
      <child>F1_03</child>
      <axis>
        <xyz>0 0 1</xyz>
        <limit>
          <lower>-0.15708</lower>
          <upper>2.53073</upper>
          <effort>10</effort>
          <velocity>5</velocity>
        </limit>
        <dynamics>
          <damping>0.1</damping>
          <friction>0.1</friction>
          <spring_reference>0</spring_reference>
          <spring_stiffness>0</spring_stiffness>
        </dynamics>
      </axis>
    </joint>
    <link name='F1_03'>
      <pose relative_to='F1M3'>0 0 0 0 -0 0</pose>
      <inertial>
        <pose>0.014 -0.000453 -4e-05 1.56511 -0.000858 1.55626</pose>
        <mass>0.051</mass>
        <inertia>
          <ixx>1.69122e-05</ixx>
          <ixy>0</ixy>
          <ixz>0</ixz>
          <iyy>1.49403e-05</iyy>
          <iyz>0</iyz>
          <izz>6.50553e-06</izz>
        </inertia>
      </inertial>
      <collision name='F1_03_collision'>
        <pose>0.019035 -0.000761 0.000157 1.54055 -0.002363 1.59946</pose>
        <geometry>
          <mesh>
            <scale>1 1 1</scale>
            <uri>model://delto3f/meshes/link_03.stl</uri>
          </mesh>
        </geometry>
      </collision>
      <visual name='F1_03_visual'>
        <pose>0.019035 -0.000761 0.000157 1.54055 -0.002363 1.59946</pose>
        <geometry>
          <mesh>
            <scale>1 1 1</scale>
            <uri>model://delto3f/meshes/link_03.stl</uri>
          </mesh>
        </geometry>
        <material>
          <ambient>0.05 0.05 0.05 1</ambient>
          <diffuse>0.1 0.1 0.1 1</diffuse>
          <specular>0.1 0.1 0.1 1</specular>
        </material>
      </visual>
      <self_collide>1</self_collide>
    </link>
    <joint name='F1M4' type='revolute'>
      <pose relative_to='F1_03'>0.0434 0 0 0 -0 0</pose>
      <parent>F1_03</parent>
      <child>F1_04</child>
      <axis>
        <xyz>0 0 1</xyz>
        <limit>
          <lower>-0.226893</lower>
          <upper>2.02458</upper>
          <effort>10</effort>
          <velocity>5</velocity>
        </limit>
        <dynamics>
          <damping>0.1</damping>
          <friction>0.1</friction>
          <spring_reference>0</spring_reference>
          <spring_stiffness>0</spring_stiffness>
        </dynamics>
      </axis>
    </joint>
    <link name='F1_04'>
      <pose relative_to='F1M4'>0 0 0 0 -0 0</pose>
      <inertial>
        <pose>0.018042 -0.000265 -3.8e-05 1.56685 -0.000869 1.58297</pose>
        <mass>0.073</mass>
        <inertia>
          <ixx>2.40164e-05</ixx>
          <ixy>-9.38541e-10</ixy>
          <ixz>2.53327e-07</ixz>
          <iyy>2.27674e-05</iyy>
          <iyz>3.04026e-08</iyz>
          <izz>6.29671e-06</izz>
        </inertia>
      </inertial>
      <collision name='F1_04_collision'>
        <pose>0.011992 -0.000773 -5e-06 1.57453 0.003601 1.66504</pose>
        <geometry>
          <mesh>
            <scale>1 1 1</scale>
            <uri>model://delto3f/meshes/link_04.stl</uri>
          </mesh>
        </geometry>
        <self_collide>1</self_collide>
      </collision>
      <collision name='F1_TIP_collision'>
        <pose>0.044959 -0.000423 0 1.57088 -1e-05 1.52041</pose>
        <geometry>
          <mesh>
            <scale>1 1 1</scale>
            <uri>model://delto3f/meshes/link_tip_high.stl</uri>
          </mesh>
        </geometry>
        <self_collide>1</self_collide>
      </collision>
      <visual name='F1_04_visual'>
        <pose>0.011992 -0.000773 -5e-06 1.57453 0.003601 1.66504</pose>
        <geometry>
          <mesh>
            <scale>1 1 1</scale>
            <uri>model://delto3f/meshes/link_04.stl</uri>
          </mesh>
        </geometry>
        <material>
          <ambient>0.05 0.05 0.05 1</ambient>
          <diffuse>0.1 0.1 0.1 1</diffuse>
          <specular>0.1 0.1 0.1 1</specular>
        </material>
      </visual>
      <visual name='F1_TIP_visual'>
        <pose>0.044959 -0.000423 0 1.57088 -1e-05 1.52041</pose>
        <geometry>
          <mesh>
            <scale>1 1 1</scale>
            <uri>model://delto3f/meshes/link_tip_high.stl</uri>
          </mesh>
        </geometry>
        <material>
          <ambient>0.9 0.9 0.9 1</ambient>
          <diffuse>0.95 0.95 0.95 1</diffuse>
          <specular>0.1 0.1 0.1 1</specular>
        </material>
      </visual>
      <self_collide>1</self_collide>
    </link>
    <joint name='F2M1' type='revolute'>
      <pose relative_to='delto_base_link'>-0.01334 0.023 0 0 0 -3.14</pose>
      <parent>delto_base_link</parent>
      <child>F2_01</child>
      <axis>
        <xyz>0 0 1</xyz>
        <limit>
          <lower>-1.91986</lower>
          <upper>0.139626</upper>
          <effort>10</effort>
          <velocity>5</velocity>
        </limit>
        <dynamics>
          <damping>0.1</damping>
          <friction>0.1</friction>
          <spring_reference>0</spring_reference>
          <spring_stiffness>0</spring_stiffness>
        </dynamics>
      </axis>
    </joint>
    <link name='F2_01'>
      <pose relative_to='F2M1'>0 0 0 0 -0 0</pose>
      <inertial>
        <pose>0.000391 0 -0.014 -0.176624 -2e-06 1.57079</pose>
        <mass>0.061</mass>
        <inertia>
          <ixx>1.924e-05</ixx>
          <ixy>0</ixy>
          <ixz>0</ixz>
          <iyy>1.70941e-05</iyy>
          <iyz>0</iyz>
          <izz>5.94788e-06</izz>
        </inertia>
      </inertial>
      <collision name='F2_01_collision'>
        <pose>0.001898 -1e-06 -0.022984 -0.144392 2e-05 1.57092</pose>
        <geometry>
          <mesh>
            <scale>1 1 1</scale>
            <uri>model://delto3f/meshes/link_01.stl</uri>
          </mesh>
        </geometry>
      </collision>
      <visual name='F2_01_visual'>
        <pose>0.001898 -1e-06 -0.022984 -0.144392 2e-05 1.57092</pose>
        <geometry>
          <mesh>
            <scale>1 1 1</scale>
            <uri>model://delto3f/meshes/link_01.stl</uri>
          </mesh>
        </geometry>
        <material>
          <ambient>0.05 0.05 0.05 1</ambient>
          <diffuse>0.1 0.1 0.1 1</diffuse>
          <specular>0.1 0.1 0.1 1</specular>
        </material>
      </visual>
      <self_collide>1</self_collide>
    </link>
    <joint name='F2M2' type='revolute'>
      <pose relative_to='F2_01'>0 0 0 -3.14 -1.57 -0</pose>
      <parent>F2_01</parent>
      <child>F2_02</child>
      <axis>
        <xyz>0 0 1</xyz>
        <limit>
          <lower>-1.76278</lower>
          <upper>1.76278</upper>
          <effort>10</effort>
          <velocity>5</velocity>
        </limit>
        <dynamics>
          <damping>0.1</damping>
          <friction>0.1</friction>
          <spring_reference>0</spring_reference>
          <spring_stiffness>0</spring_stiffness>
        </dynamics>
      </axis>
    </joint>
    <link name='F2_02'>
      <pose relative_to='F2M2'>0 0 0 0 -0 0</pose>
      <inertial>
        <pose>0.01 3e-06 0.016 -0.003689 0.316886 -0.002774</pose>
        <mass>0.025</mass>
        <inertia>
          <ixx>7.1648e-06</ixx>
          <ixy>0</ixy>
          <ixz>0</ixz>
          <iyy>6.31302e-06</iyy>
          <iyz>0</iyz>
          <izz>3.27418e-06</izz>
        </inertia>
      </inertial>
      <collision name='F2_02_collision'>
        <pose>0.010322 0.000268 0.013591 -0.031181 0.375739 -0.024334</pose>
        <geometry>
          <mesh>
            <scale>1 1 1</scale>
            <uri>model://delto3f/meshes/link_02.stl</uri>
          </mesh>
        </geometry>
        <self_collide>1</self_collide>
      </collision>
      <visual name='F2_02_visual'>
        <pose>0.010322 0.000268 0.013591 -0.031181 0.375739 -0.024334</pose>
        <geometry>
          <mesh>
            <scale>1 1 1</scale>
            <uri>model://delto3f/meshes/link_02.stl</uri>
          </mesh>
        </geometry>
        <material>
          <ambient>0.05 0.05 0.05 1</ambient>
          <diffuse>0.1 0.1 0.1 1</diffuse>
          <specular>0.1 0.1 0.1 1</specular>
        </material>
      </visual>
      <self_collide>1</self_collide>
    </link>
    <joint name='F2M3' type='revolute'>
      <pose relative_to='F2_02'>0.02022 0 0.03136 -1.57 -1.57 0</pose>
      <parent>F2_02</parent>
      <child>F2_03</child>
      <axis>
        <xyz>0 0 1</xyz>
        <limit>
          <lower>-0.15708</lower>
          <upper>2.53073</upper>
          <effort>10</effort>
          <velocity>5</velocity>
        </limit>
        <dynamics>
          <damping>0.1</damping>
          <friction>0.1</friction>
          <spring_reference>0</spring_reference>
          <spring_stiffness>0</spring_stiffness>
        </dynamics>
      </axis>
    </joint>
    <link name='F2_03'>
      <pose relative_to='F2M3'>0 0 0 0 -0 0</pose>
      <inertial>
        <pose>0.014 -0.000453 -4e-05 1.56511 -0.000858 1.55626</pose>
        <mass>0.051</mass>
        <inertia>
          <ixx>1.69122e-05</ixx>
          <ixy>0</ixy>
          <ixz>0</ixz>
          <iyy>1.49403e-05</iyy>
          <iyz>0</iyz>
          <izz>6.50553e-06</izz>
        </inertia>
      </inertial>
      <collision name='F2_03_collision'>
        <pose>0.019035 -0.000761 0.000157 1.54055 -0.002363 1.59946</pose>
        <geometry>
          <mesh>
            <scale>1 1 1</scale>
            <uri>model://delto3f/meshes/link_03.stl</uri>
          </mesh>
        </geometry>
        <self_collide>1</self_collide>
      </collision>
      <visual name='F2_03_visual'>
        <pose>0.019035 -0.000761 0.000157 1.54055 -0.002363 1.59946</pose>
        <geometry>
          <mesh>
            <scale>1 1 1</scale>
            <uri>model://delto3f/meshes/link_03.stl</uri>
          </mesh>
        </geometry>
        <material>
          <ambient>0.05 0.05 0.05 1</ambient>
          <diffuse>0.1 0.1 0.1 1</diffuse>
          <specular>0.1 0.1 0.1 1</specular>
        </material>
      </visual>
      <self_collide>1</self_collide>
    </link>
    <joint name='F2M4' type='revolute'>
      <pose relative_to='F2_03'>0.0434 0 0 0 -0 0</pose>
      <parent>F2_03</parent>
      <child>F2_04</child>
      <axis>
        <xyz>0 0 1</xyz>
        <limit>
          <lower>-0.226893</lower>
          <upper>2.02458</upper>
          <effort>10</effort>
          <velocity>5</velocity>
        </limit>
        <dynamics>
          <damping>0.1</damping>
          <friction>0.1</friction>
          <spring_reference>0</spring_reference>
          <spring_stiffness>0</spring_stiffness>
        </dynamics>
      </axis>
    </joint>
    <link name='F2_04'>
      <pose relative_to='F2M4'>0 0 0 0 -0 0</pose>
      <inertial>
        <pose>0.018042 -0.000265 -3.8e-05 1.56685 -0.000869 1.58297</pose>
        <mass>0.073</mass>
        <inertia>
          <ixx>2.40164e-05</ixx>
          <ixy>-9.38541e-10</ixy>
          <ixz>2.53327e-07</ixz>
          <iyy>2.27674e-05</iyy>
          <iyz>3.04026e-08</iyz>
          <izz>6.29671e-06</izz>
        </inertia>
      </inertial>
      <collision name='F2_04_collision'>
        <pose>0.011992 -0.000773 -5e-06 1.57453 0.003601 1.66504</pose>
        <geometry>
          <mesh>
            <scale>1 1 1</scale>
            <uri>model://delto3f/meshes/link_04.stl</uri>
          </mesh>
        </geometry>
        <self_collide>1</self_collide>
      </collision>
      <collision name='F2_TIP_collision'>
        <pose>0.044959 -0.000423 0 1.57088 -1e-05 1.52041</pose>
        <geometry>
          <mesh>
            <scale>1 1 1</scale>
            <uri>model://delto3f/meshes/link_tip_high.stl</uri>
          </mesh>
        </geometry>
        <self_collide>1</self_collide>
      </collision>
      <visual name='F2_04_visual'>
        <pose>0.011992 -0.000773 -5e-06 1.57453 0.003601 1.66504</pose>
        <geometry>
          <mesh>
            <scale>1 1 1</scale>
            <uri>model://delto3f/meshes/link_04.stl</uri>
          </mesh>
        </geometry>
        <material>
          <ambient>0.05 0.05 0.05 1</ambient>
          <diffuse>0.1 0.1 0.1 1</diffuse>
          <specular>0.1 0.1 0.1 1</specular>
        </material>
      </visual>
      <visual name='F2_TIP_visual'>
        <pose>0.044959 -0.000423 0 1.57088 -1e-05 1.52041</pose>
        <geometry>
          <mesh>
            <scale>1 1 1</scale>
            <uri>model://delto3f/meshes/link_tip_high.stl</uri>
          </mesh>
        </geometry>
        <material>
          <ambient>0.9 0.9 0.9 1</ambient>
          <diffuse>0.95 0.95 0.95 1</diffuse>
          <specular>0.1 0.1 0.1 1</specular>
        </material>
      </visual>
      <self_collide>1</self_collide>
    </link>
    <joint name='F3M1' type='revolute'>
      <pose relative_to='delto_base_link'>-0.01334 -0.023 0 0 0 -3.14</pose>
      <parent>delto_base_link</parent>
      <child>F3_01</child>
      <axis>
        <xyz>0 0 1</xyz>
        <limit>
          <lower>-0.0872665</lower>
          <upper>2.00713</upper>
          <effort>10</effort>
          <velocity>5</velocity>
        </limit>
        <dynamics>
          <damping>0.1</damping>
          <friction>0.1</friction>
          <spring_reference>0</spring_reference>
          <spring_stiffness>0</spring_stiffness>
        </dynamics>
      </axis>
    </joint>
    <link name='F3_01'>
      <pose relative_to='F3M1'>0 0 0 0 -0 0</pose>
      <inertial>
        <pose>0.000391 0 -0.014 -0.176624 -2e-06 1.57079</pose>
        <mass>0.061</mass>
        <inertia>
          <ixx>1.924e-05</ixx>
          <ixy>0</ixy>
          <ixz>0</ixz>
          <iyy>1.70941e-05</iyy>
          <iyz>0</iyz>
          <izz>5.94788e-06</izz>
        </inertia>
      </inertial>
      <collision name='F3_01_collision'>
        <pose>0.001898 -1e-06 -0.022984 -0.144392 2e-05 1.57092</pose>
        <geometry>
          <mesh>
            <scale>1 1 1</scale>
            <uri>model://delto3f/meshes/link_01.stl</uri>
          </mesh>
        </geometry>
      </collision>
      <visual name='F3_01_visual'>
        <pose>0.001898 -1e-06 -0.022984 -0.144392 2e-05 1.57092</pose>
        <geometry>
          <mesh>
            <scale>1 1 1</scale>
            <uri>model://delto3f/meshes/link_01.stl</uri>
          </mesh>
        </geometry>
        <material>
          <ambient>0.05 0.05 0.05 1</ambient>
          <diffuse>0.1 0.1 0.1 1</diffuse>
          <specular>0.1 0.1 0.1 1</specular>
        </material>
      </visual>
      <self_collide>1</self_collide>
    </link>
    <joint name='F3M2' type='revolute'>
      <pose relative_to='F3_01'>0 0 0 -3.14 -1.57 -0</pose>
      <parent>F3_01</parent>
      <child>F3_02</child>
      <axis>
        <xyz>0 0 1</xyz>
        <limit>
          <lower>-1.76278</lower>
          <upper>1.76278</upper>
          <effort>10</effort>
          <velocity>5</velocity>
        </limit>
        <dynamics>
          <damping>0.1</damping>
          <friction>0.1</friction>
          <spring_reference>0</spring_reference>
          <spring_stiffness>0</spring_stiffness>
        </dynamics>
      </axis>
    </joint>
    <link name='F3_02'>
      <pose relative_to='F3M2'>0 0 0 0 -0 0</pose>
      <inertial>
        <pose>0.01 3e-06 0.016 -0.003689 0.316886 -0.002774</pose>
        <mass>0.025</mass>
        <inertia>
          <ixx>7.1648e-06</ixx>
          <ixy>0</ixy>
          <ixz>0</ixz>
          <iyy>6.31302e-06</iyy>
          <iyz>0</iyz>
          <izz>3.27418e-06</izz>
        </inertia>
      </inertial>
      <collision name='F3_02_collision'>
        <pose>0.010322 0.000268 0.013591 -0.031181 0.375739 -0.024334</pose>
        <geometry>
          <mesh>
            <scale>1 1 1</scale>
            <uri>model://delto3f/meshes/link_02.stl</uri>
          </mesh>
        </geometry>
        <self_collide>1</self_collide>
      </collision>
      <visual name='F3_02_visual'>
        <pose>0.010322 0.000268 0.013591 -0.031181 0.375739 -0.024334</pose>
        <geometry>
          <mesh>
            <scale>1 1 1</scale>
            <uri>model://delto3f/meshes/link_02.stl</uri>
          </mesh>
        </geometry>
        <material>
          <ambient>0.05 0.05 0.05 1</ambient>
          <diffuse>0.1 0.1 0.1 1</diffuse>
          <specular>0.1 0.1 0.1 1</specular>
        </material>
      </visual>
      <self_collide>1</self_collide>
    </link>
    <joint name='F3M3' type='revolute'>
      <pose relative_to='F3_02'>0.02022 0 0.03136 -1.57 -1.57 0</pose>
      <parent>F3_02</parent>
      <child>F3_03</child>
      <axis>
        <xyz>0 0 1</xyz>
        <limit>
          <lower>-0.15708</lower>
          <upper>2.53073</upper>
          <effort>10</effort>
          <velocity>5</velocity>
        </limit>
        <dynamics>
          <damping>0.1</damping>
          <friction>0.1</friction>
          <spring_reference>0</spring_reference>
          <spring_stiffness>0</spring_stiffness>
        </dynamics>
      </axis>
    </joint>
    <link name='F3_03'>
      <pose relative_to='F3M3'>0 0 0 0 -0 0</pose>
      <inertial>
        <pose>0.014 -0.000453 -4e-05 1.56511 -0.000858 1.55626</pose>
        <mass>0.051</mass>
        <inertia>
          <ixx>1.69122e-05</ixx>
          <ixy>0</ixy>
          <ixz>0</ixz>
          <iyy>1.49403e-05</iyy>
          <iyz>0</iyz>
          <izz>6.50553e-06</izz>
        </inertia>
      </inertial>
      <collision name='F3_03_collision'>
        <pose>0.019035 -0.000761 0.000157 1.54055 -0.002363 1.59946</pose>
        <geometry>
          <mesh>
            <scale>1 1 1</scale>
            <uri>model://delto3f/meshes/link_03.stl</uri>
          </mesh>
        </geometry>
      </collision>
      <visual name='F3_03_visual'>
        <pose>0.019035 -0.000761 0.000157 1.54055 -0.002363 1.59946</pose>
        <geometry>
          <mesh>
            <scale>1 1 1</scale>
            <uri>model://delto3f/meshes/link_03.stl</uri>
          </mesh>
        </geometry>
        <material>
          <ambient>0.05 0.05 0.05 1</ambient>
          <diffuse>0.1 0.1 0.1 1</diffuse>
          <specular>0.1 0.1 0.1 1</specular>
        </material>
      </visual>
      <self_collide>1</self_collide>
    </link>
    <joint name='F3M4' type='revolute'>
      <pose relative_to='F3_03'>0.0434 0 0 0 -0 0</pose>
      <parent>F3_03</parent>
      <child>F3_04</child>
      <axis>
        <xyz>0 0 1</xyz>
        <limit>
          <lower>-0.226893</lower>
          <upper>2.02458</upper>
          <effort>10</effort>
          <velocity>5</velocity>
        </limit>
        <dynamics>
          <damping>0.1</damping>
          <friction>0.1</friction>
          <spring_reference>0</spring_reference>
          <spring_stiffness>0</spring_stiffness>
        </dynamics>
      </axis>
    </joint>
    <link name='F3_04'>
      <pose relative_to='F3M4'>0 0 0 0 -0 0</pose>
      <inertial>
        <pose>0.018042 -0.000265 -3.8e-05 1.56685 -0.000869 1.58297</pose>
        <mass>0.073</mass>
        <inertia>
          <ixx>2.40164e-05</ixx>
          <ixy>-9.38541e-10</ixy>
          <ixz>2.53327e-07</ixz>
          <iyy>2.27674e-05</iyy>
          <iyz>3.04026e-08</iyz>
          <izz>6.29671e-06</izz>
        </inertia>
      </inertial>
      <collision name='F3_04_collision'>
        <pose>0.011992 -0.000773 -5e-06 1.57453 0.003601 1.66504</pose>
        <geometry>
          <mesh>
            <scale>1 1 1</scale>
            <uri>model://delto3f/meshes/link_04.stl</uri>
          </mesh>
        </geometry>
        <self_collide>1</self_collide>
      </collision>
      <collision name='F3_TIP_collision'>
        <pose>0.044959 -0.000423 0 1.57088 -1e-05 1.52041</pose>
        <geometry>
          <mesh>
            <scale>1 1 1</scale>
            <uri>model://delto3f/meshes/link_tip_high.stl</uri>
          </mesh>
        </geometry>
        <self_collide>1</self_collide>
      </collision>
      <visual name='F3_04_visual'>
        <pose>0.011992 -0.000773 -5e-06 1.57453 0.003601 1.66504</pose>
        <geometry>
          <mesh>
            <scale>1 1 1</scale>
            <uri>model://delto3f/meshes/link_04.stl</uri>
          </mesh>
        </geometry>
        <material>
          <ambient>0.05 0.05 0.05 1</ambient>
          <diffuse>0.1 0.1 0.1 1</diffuse>
          <specular>0.1 0.1 0.1 1</specular>
        </material>
      </visual>
      <visual name='F3_TIP_visual'>
        <pose>0.044959 -0.000423 0 1.57088 -1e-05 1.52041</pose>
        <geometry>
          <mesh>
            <scale>1 1 1</scale>
            <uri>model://delto3f/meshes/link_tip_high.stl</uri>
          </mesh>
        </geometry>
        <material>
          <ambient>0.9 0.9 0.9 1</ambient>
          <diffuse>0.95 0.95 0.95 1</diffuse>
          <specular>0.1 0.1 0.1 1</specular>
        </material>
      </visual>
      <self_collide>1</self_collide>
    </link>
    <joint name='ur3_delto_joint' type='fixed'>
      <pose relative_to='wrist_3_link'>0 0 0 -1.57 0 0</pose>
      <parent>wrist_3_link</parent>
      <child>delto_base_link</child>
    </joint>
    <joint name='world_ur3_joint' type='fixed'>
      <parent>world</parent>
      <child>base_link</child>
    </joint>
    <plugin name='ignition::gazebo::systems::JointPositionController' filename='ignition-gazebo-joint-position-controller-system'>
      <joint_name>shoulder_pan_joint</joint_name>
      <p_gain>1000</p_gain>
      <i_gain>10</i_gain>
      <d_gain>150</d_gain>
      <i_max>1.0</i_max>
      <i_min>-1.0</i_min>
    </plugin>
    <plugin name='ignition::gazebo::systems::JointPositionController' filename='ignition-gazebo-joint-position-controller-system'>
      <joint_name>shoulder_lift_joint</joint_name>
      <p_gain>5000.0</p_gain>
      <i_gain>10.0</i_gain>
      <d_gain>150.0</d_gain>
      <i_max>50.0</i_max>
      <i_min>-50.0</i_min>
    </plugin>
    <plugin name='ignition::gazebo::systems::JointPositionController' filename='ignition-gazebo-joint-position-controller-system'>
      <joint_name>elbow_joint</joint_name>
      <p_gain>5000.0</p_gain>
      <i_gain>10.0</i_gain>
      <d_gain>150.0</d_gain>
      <i_max>25.0</i_max>
      <i_min>-25.0</i_min>
    </plugin>
    <plugin name='ignition::gazebo::systems::JointPositionController' filename='ignition-gazebo-joint-position-controller-system'>
      <joint_name>wrist_1_joint</joint_name>
      <p_gain>5000.0</p_gain>
      <i_gain>10.0</i_gain>
      <d_gain>150.0</d_gain>
      <i_max>50.0</i_max>
      <i_min>-50.0</i_min>
    </plugin>
    <plugin name='ignition::gazebo::systems::JointPositionController' filename='ignition-gazebo-joint-position-controller-system'>
      <joint_name>wrist_2_joint</joint_name>
      <p_gain>20.0</p_gain>
      <i_gain>1.0</i_gain>
      <d_gain>0.2</d_gain>
      <i_max>1.0</i_max>
      <i_min>-1.0</i_min>
    </plugin>
    <plugin name='ignition::gazebo::systems::JointPositionController' filename='ignition-gazebo-joint-position-controller-system'>
      <joint_name>wrist_3_joint</joint_name>
      <p_gain>20.0</p_gain>
      <i_gain>1.0</i_gain>
      <d_gain>0.2</d_gain>
      <i_max>1.0</i_max>
      <i_min>-1.0</i_min>
    </plugin>

    <plugin name='ignition::gazebo::systems::DeltoController' filename='DeltoController'>
      <fixed>0</fixed>
      <vel_scale>1.0</vel_scale>
    </plugin>

    <plugin name='ignition::gazebo::systems::JointStatePublisher' filename='ignition-gazebo-joint-state-publisher-system'>
      <joint_name>shoulder_pan_joint</joint_name>
      <joint_name>shoulder_lift_joint</joint_name>
      <joint_name>elbow_joint</joint_name>
      <joint_name>wrist_1_joint</joint_name>
      <joint_name>wrist_2_joint</joint_name>
      <joint_name>wrist_3_joint</joint_name>
      <joint_name>F1M1</joint_name>
      <joint_name>F1M2</joint_name>
      <joint_name>F1M3</joint_name>
      <joint_name>F1M4</joint_name>
      <joint_name>F2M1</joint_name>
      <joint_name>F2M2</joint_name>
      <joint_name>F2M3</joint_name>
      <joint_name>F2M4</joint_name>
      <joint_name>F3M1</joint_name>
      <joint_name>F3M2</joint_name>
      <joint_name>F3M3</joint_name>
      <joint_name>F3M4</joint_name>
    </plugin>
  </model>
</sdf>
