<sdf version='1.7'>
  <model name='ur3_dg2f'>
    <self_collide>0</self_collide>
    <link name="base_link">
			<pose relative_to="__model__">0 0 0 0 0 0</pose>
			<inertial>
				<mass>2</mass>
				<inertia>
					<ixx>0.00305317</ixx>
					<ixy>0</ixy>
					<ixz>0</ixz>
					<iyy>0.00305317</iyy>
					<iyz>0</iyz>
					<izz>0.005625</izz>
				</inertia>
			</inertial>
			<collision name="base_link_collision">
				<geometry>
					<mesh>
						<uri>model://ur3/meshes/collision/base.stl</uri>
					</mesh>
				</geometry>
			</collision>
			<visual name="base_link_visual">
				<geometry>
					<mesh>
						<uri>model://ur3/meshes/visual/base.dae</uri>
					</mesh>
				</geometry>
			</visual>
		</link>
		<joint name="shoulder_pan_joint" type="revolute">
			<pose relative_to="base_link">0 0 0.1519 0 -0 0</pose>
			<parent>base_link</parent>
			<child>shoulder_link</child>
			<axis>
				<xyz>0 0 1</xyz>
				<limit>
					<lower>-6.28319</lower>
					<upper>6.28319</upper>
					<effort>330</effort>
					<velocity>2.16</velocity>
				</limit>
				<dynamics>
					<damping>0</damping>
					<friction>0</friction>
					<spring_reference>0</spring_reference>
					<spring_stiffness>0</spring_stiffness>
				</dynamics>
			</axis>
		</joint>
		<link name="shoulder_link">
			<pose relative_to="shoulder_pan_joint">0 0 0 0 -0 0</pose>
			<inertial>
				<mass>2</mass>
				<inertia>
					<ixx>0.00809316</ixx>
					<ixy>0</ixy>
					<ixz>0</ixz>
					<iyy>0.00809316</iyy>
					<iyz>0</iyz>
					<izz>0.005625</izz>
				</inertia>
			</inertial>
			<collision name="shoulder_link_collision">
				<geometry>
					<mesh>
						<uri>model://ur3/meshes/collision/shoulder.stl</uri>
					</mesh>
				</geometry>
			</collision>
			<visual name="shoulder_link_visual">
				<geometry>
					<mesh>
						<uri>model://ur3/meshes/visual/shoulder.dae</uri>
					</mesh>
				</geometry>
			</visual>
			<self_collide>1</self_collide>
		</link>
		<joint name="shoulder_lift_joint" type="revolute">
			<pose relative_to="shoulder_link">0 0.1198 0 0 1.5708 0</pose>
			<parent>shoulder_link</parent>
			<child>upper_arm_link</child>
			<axis>
				<xyz>0 1 0</xyz>
				<limit>
					<lower>-6.28319</lower>
					<upper>6.28319</upper>
					<effort>330</effort>
					<velocity>2.16</velocity>
				</limit>
				<dynamics>
					<damping>0</damping>
					<friction>0</friction>
					<spring_reference>0</spring_reference>
					<spring_stiffness>0</spring_stiffness>
				</dynamics>
			</axis>
		</joint>
		<link name="upper_arm_link">
			<pose relative_to="shoulder_lift_joint">0 0 0 0 -0 0</pose>
			<inertial>
				<pose>0 0 0.121825 0 -0 0</pose>
				<mass>3.42</mass>
				<inertia>
					<ixx>0.0217285</ixx>
					<ixy>0</ixy>
					<ixz>0</ixz>
					<iyy>0.0217285</iyy>
					<iyz>0</iyz>
					<izz>0.00961875</izz>
				</inertia>
			</inertial>
			<collision name="upper_arm_link_collision">
				<geometry>
					<mesh>
						<uri>model://ur3/meshes/collision/upperarm.stl</uri>
					</mesh>
				</geometry>
			</collision>
			<visual name="upper_arm_link_visual">
				<geometry>
					<mesh>
						<uri>model://ur3/meshes/visual/upperarm.dae</uri>
					</mesh>
				</geometry>
			</visual>
			<self_collide>1</self_collide>
		</link>
		<joint name="elbow_joint" type="revolute">
			<pose relative_to="upper_arm_link">0 -0.0925 0.24365 0 -0 0</pose>
			<parent>upper_arm_link</parent>
			<child>forearm_link</child>
			<axis>
				<xyz>0 1 0</xyz>
				<limit>
					<lower>-3.14159</lower>
					<upper>3.14159</upper>
					<effort>150</effort>
					<velocity>3.15</velocity>
				</limit>
				<dynamics>
					<damping>0</damping>
					<friction>0</friction>
					<spring_reference>0</spring_reference>
					<spring_stiffness>0</spring_stiffness>
				</dynamics>
			</axis>
		</joint>
		<link name="forearm_link">
			<pose relative_to="elbow_joint">0 0 0 0 -0 0</pose>
			<inertial>
				<pose>0 0 0.106625 0 -0 0</pose>
				<mass>1.26</mass>
				<inertia>
					<ixx>0.00654681</ixx>
					<ixy>0</ixy>
					<ixz>0</ixz>
					<iyy>0.00654681</iyy>
					<iyz>0</iyz>
					<izz>0.00354375</izz>
				</inertia>
			</inertial>
			<collision name="forearm_link_collision">
				<geometry>
					<mesh>
						<uri>model://ur3/meshes/collision/forearm.stl</uri>
					</mesh>
				</geometry>
			</collision>
			<visual name="forearm_link_visual">
				<geometry>
					<mesh>
						<uri>model://ur3/meshes/visual/forearm.dae</uri>
					</mesh>
				</geometry>
			</visual>
			<self_collide>1</self_collide>
		</link>
		<joint name="wrist_1_joint" type="revolute">
			<pose relative_to="forearm_link">0 0 0.21325 0 1.5708 0</pose>
			<parent>forearm_link</parent>
			<child>wrist_1_link</child>
			<axis>
				<xyz>0 1 0</xyz>
				<limit>
					<lower>-6.28319</lower>
					<upper>6.28319</upper>
					<effort>54</effort>
					<velocity>3.2</velocity>
				</limit>
				<dynamics>
					<damping>0</damping>
					<friction>0</friction>
					<spring_reference>0</spring_reference>
					<spring_stiffness>0</spring_stiffness>
				</dynamics>
			</axis>
		</joint>
		<link name="wrist_1_link">
			<pose relative_to="wrist_1_joint">0 0 0 0 -0 0</pose>
			<inertial>
				<pose>0 0.08505 0 0 -0 0</pose>
				<mass>0.8</mass>
				<inertia>
					<ixx>0.002085</ixx>
					<ixy>0</ixy>
					<ixz>0</ixz>
					<iyy>0.002085</iyy>
					<iyz>0</iyz>
					<izz>0.00225</izz>
				</inertia>
			</inertial>
			<collision name="wrist_1_link_collision">
				<geometry>
					<mesh>
						<uri>model://ur3/meshes/collision/wrist1.stl</uri>
					</mesh>
				</geometry>
			</collision>
			<visual name="wrist_1_link_visual">
				<geometry>
					<mesh>
						<uri>model://ur3/meshes/visual/wrist1.dae</uri>
					</mesh>
				</geometry>
			</visual>
			<self_collide>1</self_collide>
		</link>
		<joint name="wrist_2_joint" type="revolute">
			<pose relative_to="wrist_1_link">0 0.08505 0 0 -0 0</pose>
			<parent>wrist_1_link</parent>
			<child>wrist_2_link</child>
			<axis>
				<xyz>0 0 1</xyz>
				<limit>
					<lower>-6.28319</lower>
					<upper>6.28319</upper>
					<effort>54</effort>
					<velocity>3.2</velocity>
				</limit>
				<dynamics>
					<damping>0</damping>
					<friction>0</friction>
					<spring_reference>0</spring_reference>
					<spring_stiffness>0</spring_stiffness>
				</dynamics>
			</axis>
		</joint>
		<link name="wrist_2_link">
			<pose relative_to="wrist_2_joint">0 0 0 0 -0 0</pose>
			<inertial>
				<pose>0 0 0.08535 0 -0 0</pose>
				<mass>0.8</mass>
				<inertia>
					<ixx>0.002085</ixx>
					<ixy>0</ixy>
					<ixz>0</ixz>
					<iyy>0.002085</iyy>
					<iyz>0</iyz>
					<izz>0.00225</izz>
				</inertia>
			</inertial>
			<collision name="wrist_2_link_collision">
				<geometry>
					<mesh>
						<uri>model://ur3/meshes/collision/wrist2.stl</uri>
					</mesh>
				</geometry>
			</collision>
			<visual name="wrist_2_link_visual">
				<geometry>
					<mesh>
						<uri>model://ur3/meshes/visual/wrist2.dae</uri>
					</mesh>
				</geometry>
			</visual>
			<self_collide>1</self_collide>
		</link>
		<joint name="wrist_3_joint" type="revolute">
			<pose relative_to="wrist_2_link">0 0 0.08535 0 -0 0</pose>
			<parent>wrist_2_link</parent>
			<child>wrist_3_link</child>
			<axis>
				<xyz>0 1 0</xyz>
				<limit>
					<lower>-6.28319</lower>
					<upper>6.28319</upper>
					<effort>54</effort>
					<velocity>3.2</velocity>
				</limit>
				<dynamics>
					<damping>0</damping>
					<friction>0</friction>
					<spring_reference>0</spring_reference>
					<spring_stiffness>0</spring_stiffness>
				</dynamics>
			</axis>
		</joint>
		<link name="wrist_3_link">
			<pose relative_to="wrist_3_joint">0 0 0 0 -0 0</pose>
			<inertial>
				<pose>0 0.0619 0 1.5708 -0 0</pose>
				<mass>0.35</mass>
				<inertia>
					<ixx>0.000136267</ixx>
					<ixy>0</ixy>
					<ixz>0</ixz>
					<iyy>0.000136267</iyy>
					<iyz>0</iyz>
					<izz>0.0001792</izz>
				</inertia>
			</inertial>
			<collision name="wrist_3_link_collision">
				<geometry>
					<mesh>
						<uri>model://ur3/meshes/collision/wrist3.stl</uri>
					</mesh>
				</geometry>
			</collision>
			<visual name="wrist_3_link_visual">
				<geometry>
					<mesh>
						<uri>model://ur3/meshes/visual/wrist3.dae</uri>
					</mesh>
				</geometry>
			</visual>
			<self_collide>1</self_collide>
		</link>

	
    <link name='delto_base_link'>
    <pose relative_to='ur3_delto_joint'>0 0 0 0 0 1.57</pose>
      <inertial>
        <pose>-0.000297512898704039 0.0601358449140221 0.000405289272635231 0 0 0</pose>
        <mass>0.14811829237101701</mass>
        <inertia>
          <ixx>0.000127380225676606</ixx>
          <ixy>2.4503269576101199e-06</ixy>
          <ixz>-4.42797188296029e-07</ixz>
          <iyy>0.00013424939645262601</iyy>
          <iyz>-1.2500531830166299e-07</iyz>
          <izz>0.00012653013005572801</izz>
        </inertia>
      </inertial>
      <collision name='delto_base_link_collision'>
        <pose>0 0 0 0 0 0</pose>
        <geometry>
          <mesh>
            <scale>1 1 1</scale>
            <uri>model://DG2F/delto_base_link.stl</uri>
          </mesh>
        </geometry>
      </collision>
      <visual name='delto_base_link_visual'>
        <pose>0 0 0 0 0 0</pose>
        <geometry>
          <mesh>
            <scale>1 1 1</scale>
            <uri>model://DG2F/delto_base_link.dae</uri>
          </mesh>
        </geometry>
      </visual>
    </link>
    <joint name='Distance' type='prismatic'>
      <pose relative_to='delto_base_link'>0 0 0.113 1.5708 0 3.141588307179587</pose>
      <parent>delto_base_link</parent>
      <child>TIP1</child>
      <axis>
        <xyz>-1 0 0</xyz>
        <limit>
          <lower>0</lower>
          <upper>0.025000000000000001</upper>
          <effort>1000</effort>
          <velocity>0.5</velocity>
        </limit>
        <dynamics>
          <spring_reference>0</spring_reference>
          <spring_stiffness>0</spring_stiffness>
        </dynamics>
      </axis>
    </joint>
    <link name='TIP1'>
      <pose relative_to='Distance'>0 0 0 0 0 0</pose>
      <inertial>
        <pose>-0.018892 0.020144 0.008141499999999999 0 0 0</pose>
        <mass>0.0050620999999999999</mass>
        <inertia>
          <ixx>5.5156e-07</ixx>
          <ixy>1.1032e-07</ixy>
          <ixz>-8.5307999999999999e-08</ixz>
          <iyy>3.9644999999999998e-07</iyy>
          <iyz>1.1084000000000001e-07</iyz>
          <izz>4.9987999999999995e-07</izz>
        </inertia>
      </inertial>
      <collision name='TIP1_collision'>
        <pose>0.025 0 0 0 0 0</pose>
        <geometry>
          <mesh>
            <scale>1 1 1</scale>
            <uri>model://DG2F/TIP.stl</uri>
          </mesh>
        </geometry>
      </collision>
      <visual name='TIP1_visual'>
        <pose>0.025 0 0 0 0 0</pose>
        <geometry>
          <mesh>
            <scale>1 1 1</scale>
            <uri>model://DG2F/TIP.stl</uri>
          </mesh>
        </geometry>
        <material>
          <diffuse>0.245 0.245 0.245 1</diffuse>
          <ambient>0.245 0.245 0.245 1</ambient>
        </material>
      </visual>
	  <self_collide>0</self_collide>
    </link>
    <joint name='JOINT2' type='prismatic'>
      <pose relative_to='delto_base_link'>0 0 0.113 1.5708 0 0.0070478</pose>
      <parent>delto_base_link</parent>
      <child>TIP2</child>
      <axis>
        <xyz>-1 0 0</xyz>
        <limit>
          <lower>0</lower>
          <upper>0.025000000000000001</upper>
          <effort>1000</effort>
          <velocity>0.5</velocity>
        </limit>
        <dynamics>
          <spring_reference>0</spring_reference>
          <spring_stiffness>0</spring_stiffness>
        </dynamics>
      </axis>
    </joint>
    <link name='TIP2'>
      <pose relative_to='JOINT2'>0 0 0 0 0 0</pose>
      <inertial>
        <pose>-0.018833 0.020144 0.008141499999999999 0 0 0</pose>
        <mass>0.0050620999999999999</mass>
        <inertia>
          <ixx>5.5156e-07</ixx>
          <ixy>1.1032e-07</ixy>
          <ixz>-8.5307999999999999e-08</ixz>
          <iyy>3.9644999999999998e-07</iyy>
          <iyz>1.1084000000000001e-07</iyz>
          <izz>4.9987999999999995e-07</izz>
        </inertia>
      </inertial>
      <collision name='TIP2_collision'>
        <pose>0.025 0 0 0 0 0</pose>
        <geometry>
          <mesh>
            <scale>1 1 1</scale>
            <uri>model://DG2F/TIP.stl</uri>
          </mesh>
        </geometry>
      </collision>
      <visual name='TIP2_visual'>
        <pose>0.025 0 0 0 0 0</pose>
        <geometry>
          <mesh>
            <scale>1 1 1</scale>
            <uri>model://DG2F/TIP.stl</uri>
          </mesh>
        </geometry>
        <material>
          <diffuse>0.245 0.245 0.245 1</diffuse>
          <ambient>0.245 0.245 0.245 1</ambient>
        </material>
      </visual>
	  <self_collide>0</self_collide>
    </link>
    
    <joint name='ur3_delto_joint' type='fixed'>
      <pose relative_to='wrist_3_link'>0 0.08 0 -1.57 0 0</pose>
      <parent>wrist_3_link</parent>
      <child>delto_base_link</child>
    </joint>
    
    <joint name='world_ur3_joint' type='fixed'>
      <parent>world</parent>
      <child>base_link</child>
    </joint>
    
	
	<joint name='ee_fixed_joint' type='fixed'>
      <pose relative_to='wrist_3_link'>0 0.0922 0 0 -0 1.5708</pose>
      <parent>wrist_3_link</parent>
      <child>ee_link</child>
    </joint>
	
    <link name='ee_link'>
      <inertial>
        <mass>0.001</mass>
        <inertia>
          <ixx>1.66667e-08</ixx>
          <ixy>0</ixy>
          <ixz>0</ixz>
          <iyy>1.66667e-08</iyy>
          <iyz>0</iyz>
          <izz>1.66667e-08</izz>
        </inertia>
      </inertial>
      <collision name='collision'>
        <geometry>
          <box>
            <size>0.01 0.01 0.01</size>
          </box>
        </geometry>
      </collision>
    </link>
    
    <plugin name='ignition::gazebo::systems::JointPositionController' filename='ignition-gazebo-joint-position-controller-system'>
      <joint_name>shoulder_pan_joint</joint_name>
      <p_gain>1000</p_gain>
      <i_gain>10</i_gain>
      <d_gain>150</d_gain>
      <i_max>1.0</i_max>
      <i_min>-1.0</i_min>
    </plugin>
    <plugin name='ignition::gazebo::systems::JointPositionController' filename='ignition-gazebo-joint-position-controller-system'>
      <joint_name>shoulder_lift_joint</joint_name>
      <p_gain>5000.0</p_gain>
      <i_gain>10.0</i_gain>
      <d_gain>150.0</d_gain>
      <i_max>50.0</i_max>
      <i_min>-50.0</i_min>
    </plugin>
    <plugin name='ignition::gazebo::systems::JointPositionController' filename='ignition-gazebo-joint-position-controller-system'>
      <joint_name>elbow_joint</joint_name>
      <p_gain>5000.0</p_gain>
      <i_gain>10.0</i_gain>
      <d_gain>150.0</d_gain>
      <i_max>25.0</i_max>
      <i_min>-25.0</i_min>
    </plugin>
    <plugin name='ignition::gazebo::systems::JointPositionController' filename='ignition-gazebo-joint-position-controller-system'>
      <joint_name>wrist_1_joint</joint_name>
      <p_gain>5000.0</p_gain>
      <i_gain>10.0</i_gain>
      <d_gain>150.0</d_gain>
      <i_max>50.0</i_max>
      <i_min>-50.0</i_min>
    </plugin>
    <plugin name='ignition::gazebo::systems::JointPositionController' filename='ignition-gazebo-joint-position-controller-system'>
      <joint_name>wrist_2_joint</joint_name>
      <p_gain>20.0</p_gain>
      <i_gain>1.0</i_gain>
      <d_gain>0.2</d_gain>
      <i_max>1.0</i_max>
      <i_min>-1.0</i_min>
    </plugin>
    <plugin name='ignition::gazebo::systems::JointPositionController' filename='ignition-gazebo-joint-position-controller-system'>
      <joint_name>wrist_3_joint</joint_name>
      <p_gain>20.0</p_gain>
      <i_gain>1.0</i_gain>
      <d_gain>0.2</d_gain>
      <i_max>1.0</i_max>
      <i_min>-1.0</i_min>
    </plugin>

    <plugin name='ignition::gazebo::systems::Dg2fController' filename='Dg2fController'>
      <fixed>0</fixed>
      <vel_scale>1.0</vel_scale>
	  <kp>10.0</kp>
	  <kd>8.0</kd>
    </plugin>

    <plugin name='ignition::gazebo::systems::JointStatePublisher' filename='ignition-gazebo-joint-state-publisher-system'>
      <joint_name>shoulder_pan_joint</joint_name>
      <joint_name>shoulder_lift_joint</joint_name>
      <joint_name>elbow_joint</joint_name>
      <joint_name>wrist_1_joint</joint_name>
      <joint_name>wrist_2_joint</joint_name>
      <joint_name>wrist_3_joint</joint_name>
      <joint_name>Distance</joint_name>
    </plugin>
  </model>
</sdf>
